Workbook

Sheet Employees
L1: Basic Formula pactice
A2: Employee_ID | B2: Employee_Name | C2: Department | D2: Job_Title | E2: Salary | F2: Hire_Date | G2: Office_Location | H2: Email | I2: Phone | K2: Example | L2: value
A3: EMP1001 | B3: Sarah Smith | C3: Operations | D3: Specialist | E3: 72098 | F3: 2017-07-03 | G3: Chicago | H3: employee1@company.com | I3: 555-854-2679 | K3: 1. Total PayRole cost | L3: =SUM(E3:E52) -> 3923380
A4: EMP1002 | B4: William Johnson | C4: Finance | D4: Coordinator | E4: 44165 | F4: 2015-05-03 | G4: New York | H4: employee2@company.com | I4: 555-323-4811 | K4: 2.Average pay | L4: =AVERAGE(E3:E52) -> 78467.6
A5: EMP1003 | B5: William Smith | C5: Finance | D5: Manager | E5: 111426 | F5: 2019-09-15 | G5: Chicago | H5: employee3@company.com | I5: 555-559-5557 | K5: 3.Number of employees | L5: =COUNTA(A3:A52) -> 50
A6: EMP1004 | B6: John Williams | C6: Operations | D6: Coordinator | E6: 84597 | F6: 2018-02-12 | G6: Chicago | H6: employee4@company.com | I6: 555-320-6514 | K6: 4.Top earner | L6: =MAX(E3:E52) -> 116569
A7: EMP1005 | B7: Sarah Johnson | C7: HR | D7: Analyst | E7: 87052 | F7: 2018-11-09 | G7: Seattle | H7: employee5@company.com | I7: 555-370-1711 | K7: 5.Minimum salary | L7: =MIN(E3:E52) -> 41220
A8: EMP1006 | B8: Jennifer Johnson | C8: HR | D8: Analyst | E8: 112357 | F8: 2018-04-15 | G8: Seattle | H8: employee6@company.com | I8: 555-982-6925 | K8: 6. No. of Operations employees | L8: =COUNTIF(C2:C52, "Operations") -> 10
A9: EMP1007 | B9: Jessica Brown | C9: Operations | D9: Analyst | E9: 46006 | F9: 2022-06-01 | G9: Chicago | H9: employee7@company.com | I9: 555-891-5741 | K9: 7. No. of Sales employess | L9: =COUNTIF(C2:C52, "Sales") -> 11
A10: EMP1008 | B10: Sarah Brown | C10: Sales | D10: Coordinator | E10: 76434 | F10: 2020-02-01 | G10: San Francisco | H10: employee8@company.com | I10: 555-266-7065 | K10: 8. No. of HR employees | L10: =COUNTIF(C2:C52, "HR") -> 7
A11: EMP1009 | B11: Lisa Brown | C11: Operations | D11: Specialist | E11: 49358 | F11: 2021-10-31 | G11: Chicago | H11: employee9@company.com | I11: 555-646-5010 | K11: 9. No. of Finance employess | L11: =COUNTIF(C2:C52, "Finance") -> 9
A12: EMP1010 | B12: Michael Davis | C12: HR | D12: Specialist | E12: 113000 | F12: 2017-06-18 | G12: San Francisco | H12: employee10@company.com | I12: 555-963-1916 | K12: 10. No. of Marketing employess | L12: =COUNTIF(C2:C52, "Marketing") -> 8
A13: EMP1011 | B13: Emily Smith | C13: IT | D13: Coordinator | E13: 75093 | F13: 2015-09-29 | G13: Chicago | H13: employee11@company.com | I13: 555-680-6155 | K13: 11. No. of IT employess | L13: =COUNTIF(C2:C52, "IT") -> 5
A14: EMP1012 | B14: Emily Davis | C14: HR | D14: Coordinator | E14: 58726 | F14: 2017-12-20 | G14: Chicago | H14: employee12@company.com | I14: 555-352-9830
A15: EMP1013 | B15: David Miller | C15: Finance | D15: Coordinator | E15: 87447 | F15: 2017-06-17 | G15: Chicago | H15: employee13@company.com | I15: 555-621-9085
A16: EMP1014 | B16: Sarah Smith | C16: Sales | D16: Manager | E16: 60969 | F16: 2022-08-19 | G16: Boston | H16: employee14@company.com | I16: 555-710-2040 | K16: Text Functions Practice
A17: EMP1015 | B17: Robert Miller | C17: Finance | D17: Coordinator | E17: 109352 | F17: 2017-10-26 | G17: Seattle | H17: employee15@company.com | I17: 555-981-1188 | K17: Example | L17: values
A18: EMP1016 | B18: Sarah Jones | C18: Operations | D18: Specialist | E18: 54621 | F18: 2018-04-17 | G18: Boston | H18: employee16@company.com | I18: 555-261-8433 | K18: Extract first name | L18: =LEFT(B3,5) -> Sarah
A19: EMP1017 | B19: John Jones | C19: Finance | D19: Manager | E19: 106542 | F19: 2016-03-11 | G19: San Francisco | H19: employee17@company.com | I19: 555-961-9317 | K19: Extract last name | L19: =RIGHT(B3,5) -> Smith
A20: EMP1018 | B20: Jessica Brown | C20: Marketing | D20: Specialist | E20: 61174 | F20: 2021-01-18 | G20: Seattle | H20: employee18@company.com | I20: 555-100-6310 | K20: get domain from email | L20: =RIGHT(H3,(LEN(H3)+1)-FIND("@",H3)) -> @company.com
A21: EMP1019 | B21: Jennifer Smith | C21: Sales | D21: Specialist | E21: 80306 | F21: 2017-09-07 | G21: New York | H21: employee19@company.com | I21: 555-346-2290 | K21: clean extra spaces | L21: =TRIM(A2) -> Employee_ID
A22: EMP1020 | B22: Sarah Davis | C22: Sales | D22: Director | E22: 56483 | F22: 2016-06-09 | G22: Boston | H22: employee20@company.com | I22: 555-662-3705
A23: EMP1021 | B23: David Miller | C23: Marketing | D23: Director | E23: 66365 | F23: 2022-12-30 | G23: San Francisco | H23: employee21@company.com | I23: 555-508-7118
A24: EMP1022 | B24: Jennifer Davis | C24: Sales | D24: Manager | E24: 69451 | F24: 2015-09-20 | G24: San Francisco | H24: employee22@company.com | I24: 555-121-4770 | K24: Date Functions Practice
A25: EMP1023 | B25: Jessica Brown | C25: Sales | D25: Analyst | E25: 47716 | F25: 2017-07-26 | G25: New York | H25: employee23@company.com | I25: 555-132-6413 | K25: Example | L25: values
A26: EMP1024 | B26: Sarah Brown | C26: IT | D26: Coordinator | E26: 68080 | F26: 2021-01-17 | G26: Chicago | H26: employee24@company.com | I26: 555-840-8744 | K26: Calculate years expeience | L26: =DATEDIF(F3,TODAY(),"Y") -> 8
A27: EMP1025 | B27: Emily Davis | C27: HR | D27: Manager | E27: 52363 | F27: 2016-02-02 | G27: Boston | H27: employee25@company.com | I27: 555-462-7939 | K27: find hire month | L27: =TEXT(F3,"mmmm") -> July
A28: EMP1026 | B28: Robert Davis | C28: Operations | D28: Analyst | E28: 52899 | F28: 2015-09-06 | G28: Boston | H28: employee26@company.com | I28: 555-845-6559 | K28: find employees hired after 2020 | L28: =IF(YEAR(F3:F52)>2020, "YES", "NO") -> NO
A29: EMP1027 | B29: Sarah Brown | C29: Marketing | D29: Manager | E29: 110292 | F29: 2020-01-12 | G29: Chicago | H29: employee27@company.com | I29: 555-532-4006
A30: EMP1028 | B30: David Davis | C30: Marketing | D30: Analyst | E30: 98082 | F30: 2021-03-04 | G30: New York | H30: employee28@company.com | I30: 555-151-9856
A31: EMP1029 | B31: John Johnson | C31: Marketing | D31: Manager | E31: 93269 | F31: 2020-06-12 | G31: Boston | H31: employee29@company.com | I31: 555-318-7570 | K31: Lookup & Reference Functions | L31: Use INDEX-MATCH combo
A32: EMP1030 | B32: John Williams | C32: HR | D32: Analyst | E32: 91173 | F32: 2017-12-22 | G32: Boston | H32: employee30@company.com | I32: 555-392-7930 | K32: Example | L32: values
A33: EMP1031 | B33: William Davis | C33: Marketing | D33: Manager | E33: 78890 | F33: 2017-06-10 | G33: New York | H33: employee31@company.com | I33: 555-693-9883 | K33: Lookup salary by employee name | L33: =INDEX($E$2:$E$52, MATCH(B5, $B$2:$B$52, 0)) -> 111426
A34: EMP1032 | B34: John Garcia | C34: Sales | D34: Analyst | E34: 116569 | F34: 2020-05-06 | G34: Seattle | H34: employee32@company.com | I34: 555-973-9701 | K34: Use INDEX-MATCH combo(sarah smith salary) | L34: =INDEX(E2:E52, MATCH("Sarah Smith", B2:B52, 0)) -> 72098
A35: EMP1033 | B35: Michael Smith | C35: Finance | D35: Analyst | E35: 64356 | F35: 2015-10-08 | G35: Seattle | H35: employee33@company.com | I35: 555-169-4853 | K35: Find department from employee ID | L35: =INDEX(C3:C52, MATCH("EMP1007",A3:A52,0)) -> Operations
A36: EMP1034 | B36: Robert Johnson | C36: Finance | D36: Manager | E36: 115880 | F36: 2021-09-01 | G36: New York | H36: employee34@company.com | I36: 555-734-2343 | K36: VLOOKUP | L36: USED THIS FORMULA …IN SHEET Sales transactions
A37: EMP1035 | B37: Robert Garcia | C37: IT | D37: Manager | E37: 81180 | F37: 2017-09-04 | G37: San Francisco | H37: employee35@company.com | I37: 555-505-3144 | K37: HLOOKUP
A38: EMP1036 | B38: David Davis | C38: IT | D38: Analyst | E38: 41220 | F38: 2020-02-21 | G38: Seattle | H38: employee36@company.com | I38: 555-676-2638 | K38: fetch the unit price for each product code. | L38: 489
A39: EMP1037 | B39: Sarah Brown | C39: Finance | D39: Specialist | E39: 57361 | F39: 2018-11-30 | G39: New York | H39: employee37@company.com | I39: 555-350-7054 | K39: Find Stock_Quantity of Product_Code in another cell | L39: 165
A40: EMP1038 | B40: David Williams | C40: HR | D40: Director | E40: 79651 | F40: 2021-11-10 | G40: Seattle | H40: employee38@company.com | I40: 555-108-5905
...

Sheet Product_catalog
A1: Product_Code | B1: P100 | C1: P101 | D1: P102 | E1: P103 | F1: P104 | G1: P105 | H1: P106 | I1: P107 | J1: P108 | K1: P109 | L1: P110 | M1: P111 | N1: P112 | O1: P113 | P1: P114 | Q1: P115 | R1: P116 | S1: P117 | T1: P118 | U1: P119 | V1: P120
A2: Product_Name | B2: Tablet | C2: Printer | D2: Tablet | E2: Mouse | F2: Laptop | G2: Laptop | H2: Desk | I2: Desktop | J2: Mouse | K2: Chair | L2: Desktop | M2: Mouse | N2: Mouse | O2: Laptop | P2: Keyboard | Q2: Printer | R2: Chair | S2: Tablet | T2: Keyboard | U2: Desk | V2: Desktop
A3: Category | B3: Office Supplies | C3: Furniture | D3: Furniture | E3: Electronics | F3: Furniture | G3: Electronics | H3: Furniture | I3: Electronics | J3: Software | K3: Office Supplies | L3: Office Supplies | M3: Electronics | N3: Furniture | O3: Software | P3: Office Supplies | Q3: Electronics | R3: Office Supplies | S3: Software | T3: Software | U3: Furniture | V3: Furniture
A4: Unit_Cost | B4: 410 | C4: 160 | D4: 489 | E4: 234 | F4: 196 | G4: 593 | H4: 428 | I4: 209 | J4: 727 | K4: 270 | L4: 744 | M4: 275 | N4: 190 | O4: 490 | P4: 123 | Q4: 370 | R4: 167 | S4: 756 | T4: 653 | U4: 391 | V4: 407
A5: Retail_Price | B5: 312 | C5: 817 | D5: 1248 | E5: 659 | F5: 1259 | G5: 540 | H5: 738 | I5: 422 | J5: 968 | K5: 1149 | L5: 1489 | M5: 909 | N5: 623 | O5: 459 | P5: 913 | Q5: 1279 | R5: 929 | S5: 841 | T5: 920 | U5: 444 | V5: 819
A6: Supplier | B6: OfficeMax | C6: Furniture Plus | D6: TechCorp | E6: Furniture Plus | F6: ElectroSupply | G6: ElectroSupply | H6: Furniture Plus | I6: TechCorp | J6: ElectroSupply | K6: TechCorp | L6: ElectroSupply | M6: TechCorp | N6: Furniture Plus | O6: OfficeMax | P6: TechCorp | Q6: ElectroSupply | R6: TechCorp | S6: TechCorp | T6: TechCorp | U6: TechCorp | V6: OfficeMax
A7: Stock_Quantity | B7: 49 | C7: 39 | D7: 165 | E7: 96 | F7: 27 | G7: 117 | H7: 155 | I7: 182 | J7: 165 | K7: 98 | L7: 144 | M7: 11 | N7: 93 | O7: 107 | P7: 121 | Q7: 156 | R7: 93 | S7: 121 | T7: 111 | U7: 140 | V7: 70
A8: Warehouse | B8: WH-Central | C8: WH-West | D8: WH-Central | E8: WH-West | F8: WH-East | G8: WH-West | H8: WH-Central | I8: WH-East | J8: WH-West | K8: WH-West | L8: WH-Central | M8: WH-East | N8: WH-East | O8: WH-Central | P8: WH-East | Q8: WH-West | R8: WH-East | S8: WH-East | T8: WH-West | U8: WH-Central | V8: WH-East
A10: fetch the unit price for each product code.
A12: =HLOOKUP("P102",A1:V8, 4, FALSE) -> 489
A13: Find Stock_Quantity of Product_Code in another cell
A15: =HLOOKUP(J1, A1:V8, 7, FALSE) -> 165

Sheet Sales transactions
A1: Transaction_ID | B1: Transaction_Date | C1: Employee_ID | D1: Product_Code | E1: Quantity | F1: Unit_Price | G1: Employee_Name | H1: Department | I1: Job_Title
A2: TXN5001 | B2: 2024-06-25 | C2: EMP1047 | D2: P110 | E2: 7 | F2: 1299 | G2: =IFERROR(VLOOKUP(C2, Employees!A:I, 2, FALSE), "Not Found") -> Sarah Miller | H2: =IFERROR(VLOOKUP(C2, Employees!A:I, 3, FALSE), "Not Found") -> Sales | I2: =IFERROR(VLOOKUP(C2,Employees!A:I, 4, FALSE), "NOT FOUND") -> Coordinator
A3: TXN5002 | B3: 2024-09-18 | C3: EMP1008 | D3: P112 | E3: 10 | F3: 499 | G3: =IFERROR(VLOOKUP(C3, Employees!A:I, 2, FALSE), "Not Found") -> Sarah Brown | H3: =IFERROR(VLOOKUP(C3, Employees!A:I, 3, FALSE), "Not Found") -> Sales | I3: =IFERROR(VLOOKUP(C3,Employees!A:I, 4, FALSE), "NOT FOUND") -> Coordinator
A4: TXN5003 | B4: 2024-05-10 | C4: EMP1003 | D4: P113 | E4: 1 | F4: 1299 | G4: =IFERROR(VLOOKUP(C4, Employees!A:I, 2, FALSE), "Not Found") -> William Smith | H4: =IFERROR(VLOOKUP(C4, Employees!A:I, 3, FALSE), "Not Found") -> Finance | I4: =IFERROR(VLOOKUP(C4,Employees!A:I, 4, FALSE), "NOT FOUND") -> Manager
A5: TXN5004 | B5: 2024-10-02 | C5: EMP1044 | D5: P106 | E5: 6 | F5: 999 | G5: =IFERROR(VLOOKUP(C5, Employees!A:I, 2, FALSE), "Not Found") -> Robert Williams | H5: =IFERROR(VLOOKUP(C5, Employees!A:I, 3, FALSE), "Not Found") -> Sales | I5: =IFERROR(VLOOKUP(C5,Employees!A:I, 4, FALSE), "NOT FOUND") -> Specialist
A6: TXN5005 | B6: 2024-02-05 | C6: EMP1043 | D6: P110 | E6: 10 | F6: 799 | G6: =IFERROR(VLOOKUP(C6, Employees!A:I, 2, FALSE), "Not Found") -> Sarah Johnson | H6: =IFERROR(VLOOKUP(C6, Employees!A:I, 3, FALSE), "Not Found") -> Operations | I6: =IFERROR(VLOOKUP(C6,Employees!A:I, 4, FALSE), "NOT FOUND") -> Manager
A7: TXN5006 | B7: 2024-03-04 | C7: EMP1047 | D7: P109 | E7: 9 | F7: 799 | G7: =IFERROR(VLOOKUP(C7, Employees!A:I, 2, FALSE), "Not Found") -> Sarah Miller | H7: =IFERROR(VLOOKUP(C7, Employees!A:I, 3, FALSE), "Not Found") -> Sales | I7: =IFERROR(VLOOKUP(C7,Employees!A:I, 4, FALSE), "NOT FOUND") -> Coordinator
A8: TXN5007 | B8: 2024-07-28 | C8: EMP1021 | D8: P112 | E8: 5 | F8: 1299 | G8: =IFERROR(VLOOKUP(C8, Employees!A:I, 2, FALSE), "Not Found") -> David Miller | H8: =IFERROR(VLOOKUP(C8, Employees!A:I, 3, FALSE), "Not Found") -> Marketing | I8: =IFERROR(VLOOKUP(C8,Employees!A:I, 4, FALSE), "NOT FOUND") -> Director
A9: TXN5008 | B9: 2024-03-06 | C9: EMP1013 | D9: P113 | E9: 7 | F9: 1499 | G9: =IFERROR(VLOOKUP(C9, Employees!A:I, 2, FALSE), "Not Found") -> David Miller | H9: =IFERROR(VLOOKUP(C9, Employees!A:I, 3, FALSE), "Not Found") -> Finance | I9: =IFERROR(VLOOKUP(C9,Employees!A:I, 4, FALSE), "NOT FOUND") -> Coordinator
A10: TXN5009 | B10: 2024-03-30 | C10: EMP1040 | D10: P118 | E10: 5 | F10: 999 | G10: =IFERROR(VLOOKUP(C10, Employees!A:I, 2, FALSE), "Not Found") -> Jessica Brown | H10: =IFERROR(VLOOKUP(C10, Employees!A:I, 3, FALSE), "Not Found") -> Operations | I10: =IFERROR(VLOOKUP(C10,Employees!A:I, 4, FALSE), "NOT FOUND") -> Specialist
A11: TXN5010 | B11: 2024-10-07 | C11: EMP1001 | D11: P109 | E11: 5 | F11: 499 | G11: =IFERROR(VLOOKUP(C11, Employees!A:I, 2, FALSE), "Not Found") -> Sarah Smith | H11: =IFERROR(VLOOKUP(C11, Employees!A:I, 3, FALSE), "Not Found") -> Operations | I11: =IFERROR(VLOOKUP(C11,Employees!A:I, 4, FALSE), "NOT FOUND") -> Specialist
A12: TXN5011 | B12: 2024-08-08 | C12: EMP1038 | D12: P119 | E12: 6 | F12: 999 | G12: =IFERROR(VLOOKUP(C12, Employees!A:I, 2, FALSE), "Not Found") -> David Williams | H12: =IFERROR(VLOOKUP(C12, Employees!A:I, 3, FALSE), "Not Found") -> HR | I12: =IFERROR(VLOOKUP(C12,Employees!A:I, 4, FALSE), "NOT FOUND") -> Director
A13: TXN5012 | B13: 2024-08-14 | C13: EMP1029 | D13: P106 | E13: 9 | F13: 999 | G13: =IFERROR(VLOOKUP(C13, Employees!A:I, 2, FALSE), "Not Found") -> John Johnson | H13: =IFERROR(VLOOKUP(C13, Employees!A:I, 3, FALSE), "Not Found") -> Marketing | I13: =IFERROR(VLOOKUP(C13,Employees!A:I, 4, FALSE), "NOT FOUND") -> Manager
... A201: TXN5200 | B201: 2024-06-30 | C201: EMP1043 | D201: P113 | E201: 1 | F201: 799 | G201: =IFERROR(VLOOKUP(C201, Employees!A:I, 2, FALSE), "Not Found") -> Sarah Johnson | H201: =IFERROR(VLOOKUP(C201, Employees!A:I, 3, FALSE), "Not Found") -> Operations | I201: =IFERROR(VLOOKUP(C201,Employees!A:I, 4, FALSE), "NOT FOUND") -> Manager
